<sdf version='1.10'>
  <world name='factory'>
    <gravity>0 0 -9.8100000000000005</gravity>
    <magnetic_field>5.5644999999999998e-06 2.2875799999999999e-05 -4.2388400000000002e-05</magnetic_field>
    <atmosphere type='adiabatic'/>
    <physics type='ode'>
      <max_step_size>0.001</max_step_size>
      <real_time_factor>1</real_time_factor>
      <real_time_update_rate>1000</real_time_update_rate>
    </physics>
    <scene>
      <ambient>0.400000006 0.400000006 0.400000006 1</ambient>
      <background>0.699999988 0.699999988 0.699999988 1</background>
      <shadows>true</shadows>
    </scene>
    <model name='ground'>
      <static>true</static>
      <link name='link'>
        <collision name='col'>
          <geometry>
            <plane>
              <normal>0 0 1</normal>
              <size>100 100</size>
            </plane>
          </geometry>
          <surface>
            <friction>
              <ode/>
            </friction>
            <bounce/>
            <contact/>
          </surface>
        </collision>
        <visual name='vis'>
          <geometry>
            <plane>
              <normal>0 0 1</normal>
              <size>100 100</size>
            </plane>
          </geometry>
          <material>
            <ambient>0.800000012 0.800000012 0.800000012 1</ambient>
            <diffuse>0.800000012 0.800000012 0.800000012 1</diffuse>
          </material>
        </visual>
        <pose>0 0 0 0 0 0</pose>
        <inertial>
          <pose>0 0 0 0 0 0</pose>
          <mass>1</mass>
          <inertia>
            <ixx>1</ixx>
            <ixy>0</ixy>
            <ixz>0</ixz>
            <iyy>1</iyy>
            <iyz>0</iyz>
            <izz>1</izz>
          </inertia>
        </inertial>
        <enable_wind>false</enable_wind>
      </link>
      <pose>0 0 0 0 0 0</pose>
      <self_collide>false</self_collide>
    </model>
    <model name='box_1'>
      <static>true</static>
      <pose>1 0 0.20000000000000001 0 0 0</pose>
      <link name='link'>
        <collision name='col'>
          <geometry>
            <box>
              <size>0.40000000000000002 0.40000000000000002 0.40000000000000002</size>
            </box>
          </geometry>
          <surface>
            <friction>
              <ode/>
            </friction>
            <bounce/>
            <contact/>
          </surface>
        </collision>
        <visual name='vis'>
          <geometry>
            <box>
              <size>0.40000000000000002 0.40000000000000002 0.40000000000000002</size>
            </box>
          </geometry>
        </visual>
        <pose>0 0 0 0 0 0</pose>
        <inertial>
          <pose>0 0 0 0 0 0</pose>
          <mass>1</mass>
          <inertia>
            <ixx>1</ixx>
            <ixy>0</ixy>
            <ixz>0</ixz>
            <iyy>1</iyy>
            <iyz>0</iyz>
            <izz>1</izz>
          </inertia>
        </inertial>
        <enable_wind>false</enable_wind>
      </link>
      <self_collide>false</self_collide>
    </model>
    <model name='box_2'>
      <static>true</static>
      <pose>1.8 0.59999999999999998 0.20000000000000001 0 0 0</pose>
      <link name='link'>
        <collision name='col'>
          <geometry>
            <box>
              <size>0.40000000000000002 0.40000000000000002 0.40000000000000002</size>
            </box>
          </geometry>
          <surface>
            <friction>
              <ode/>
            </friction>
            <bounce/>
            <contact/>
          </surface>
        </collision>
        <visual name='vis'>
          <geometry>
            <box>
              <size>0.40000000000000002 0.40000000000000002 0.40000000000000002</size>
            </box>
          </geometry>
        </visual>
        <pose>0 0 0 0 0 0</pose>
        <inertial>
          <pose>0 0 0 0 0 0</pose>
          <mass>1</mass>
          <inertia>
            <ixx>1</ixx>
            <ixy>0</ixy>
            <ixz>0</ixz>
            <iyy>1</iyy>
            <iyz>0</iyz>
            <izz>1</izz>
          </inertia>
        </inertial>
        <enable_wind>false</enable_wind>
      </link>
      <self_collide>false</self_collide>
    </model>
    <model name='picarx'>
      <pose>0 0 0.029999999999999999 0 0 0</pose>
      <static>false</static>
      <allow_auto_disable>true</allow_auto_disable>
      <link name='base_link'>
        <inertial>
          <mass>0.80000000000000004</mass>
          <inertia>
            <ixx>0.002</ixx>
            <iyy>0.0040000000000000001</iyy>
            <izz>0.0050000000000000001</izz>
            <ixy>0</ixy>
            <ixz>0</ixz>
            <iyz>0</iyz>
          </inertia>
          <pose>0 0 0 0 0 0</pose>
        </inertial>
        <collision name='base_col'>
          <geometry>
            <box>
              <size>0.20000000000000001 0.12 0.029999999999999999</size>
            </box>
          </geometry>
          <surface>
            <friction>
              <ode/>
            </friction>
            <bounce/>
            <contact/>
          </surface>
        </collision>
        <visual name='base_vis'>
          <geometry>
            <box>
              <size>0.20000000000000001 0.12 0.029999999999999999</size>
            </box>
          </geometry>
          <material>
            <diffuse>0.200000003 0.200000003 0.200000003 1</diffuse>
          </material>
        </visual>
        <pose>0 0 0 0 0 0</pose>
        <enable_wind>false</enable_wind>
      </link>
      <link name='left_wheel'>
        <pose>0.02 0.065000000000000002 0.029999999999999999 3.1415926535897931 1.5707926536359933 3.1415926535897931</pose>
        <inertial>
          <mass>0.050000000000000003</mass>
          <inertia>
            <ixx>0.0001</ixx>
            <iyy>0.0001</iyy>
            <izz>0.00020000000000000001</izz>
            <ixy>0</ixy>
            <ixz>0</ixz>
            <iyz>0</iyz>
          </inertia>
          <pose>0 0 0 0 0 0</pose>
        </inertial>
        <collision name='col'>
          <geometry>
            <cylinder>
              <radius>0.029999999999999999</radius>
              <length>0.02</length>
            </cylinder>
          </geometry>
          <surface>
            <friction>
              <ode/>
            </friction>
            <bounce/>
            <contact/>
          </surface>
        </collision>
        <visual name='vis'>
          <geometry>
            <cylinder>
              <radius>0.029999999999999999</radius>
              <length>0.02</length>
            </cylinder>
          </geometry>
        </visual>
        <enable_wind>false</enable_wind>
      </link>
      <link name='right_wheel'>
        <pose>0.02 -0.065000000000000002 0.029999999999999999 3.1415926535897931 1.5707926536359933 3.1415926535897931</pose>
        <inertial>
          <mass>0.050000000000000003</mass>
          <inertia>
            <ixx>0.0001</ixx>
            <iyy>0.0001</iyy>
            <izz>0.00020000000000000001</izz>
            <ixy>0</ixy>
            <ixz>0</ixz>
            <iyz>0</iyz>
          </inertia>
          <pose>0 0 0 0 0 0</pose>
        </inertial>
        <collision name='col'>
          <geometry>
            <cylinder>
              <radius>0.029999999999999999</radius>
              <length>0.02</length>
            </cylinder>
          </geometry>
          <surface>
            <friction>
              <ode/>
            </friction>
            <bounce/>
            <contact/>
          </surface>
        </collision>
        <visual name='vis'>
          <geometry>
            <cylinder>
              <radius>0.029999999999999999</radius>
              <length>0.02</length>
            </cylinder>
          </geometry>
        </visual>
        <enable_wind>false</enable_wind>
      </link>
      <joint name='left_wheel_joint' type='revolute'>
        <parent>base_link</parent>
        <child>left_wheel</child>
        <axis>
          <xyz>0 0 1</xyz>
          <limit>
            <lower>-10000000000000000</lower>
            <upper>10000000000000000</upper>
            <effort>inf</effort>
            <velocity>inf</velocity>
            <stiffness>100000000</stiffness>
            <dissipation>1</dissipation>
          </limit>
          <dynamics>
            <spring_reference>0</spring_reference>
            <spring_stiffness>0</spring_stiffness>
            <damping>0</damping>
            <friction>0</friction>
          </dynamics>
        </axis>
        <pose>-1.0408340855860843e-17 0 6.9388939039072284e-18 0 0 0</pose>
      </joint>
      <joint name='right_wheel_joint' type='revolute'>
        <parent>base_link</parent>
        <child>right_wheel</child>
        <axis>
          <xyz>0 0 1</xyz>
          <limit>
            <lower>-10000000000000000</lower>
            <upper>10000000000000000</upper>
            <effort>inf</effort>
            <velocity>inf</velocity>
            <stiffness>100000000</stiffness>
            <dissipation>1</dissipation>
          </limit>
          <dynamics>
            <spring_reference>0</spring_reference>
            <spring_stiffness>0</spring_stiffness>
            <damping>0</damping>
            <friction>0</friction>
          </dynamics>
        </axis>
        <pose>-1.0408340855860843e-17 0 6.9388939039072284e-18 0 0 0</pose>
      </joint>
      <link name='sonar_link'>
        <pose>0.11 0 0.050000000000000003 0 0 0</pose>
        <sensor name='front_scan' type='gpu_lidar'>
          <pose>0 0 0 0 0 0</pose>
          <topic>front_scan</topic>
          <update_rate>20</update_rate>
          <enable_metrics>false</enable_metrics>
          <lidar>
            <scan>
              <horizontal>
                <samples>9</samples>
                <resolution>1</resolution>
                <min_angle>-0.45000000000000001</min_angle>
                <max_angle>0.45000000000000001</max_angle>
              </horizontal>
              <vertical>
                <samples>1</samples>
                <min_angle>0</min_angle>
                <max_angle>0</max_angle>
                <resolution>1</resolution>
              </vertical>
            </scan>
            <range>
              <min>0.02</min>
              <max>3</max>
              <resolution>0</resolution>
            </range>
            <noise>
              <type>none</type>
              <mean>0</mean>
              <stddev>0</stddev>
            </noise>
            <visibility_mask>4294967295</visibility_mask>
          </lidar>
        </sensor>
        <inertial>
          <pose>0 0 0 0 0 0</pose>
          <mass>1</mass>
          <inertia>
            <ixx>1</ixx>
            <ixy>0</ixy>
            <ixz>0</ixz>
            <iyy>1</iyy>
            <iyz>0</iyz>
            <izz>1</izz>
          </inertia>
        </inertial>
        <enable_wind>false</enable_wind>
      </link>
      <link name='camera_link'>
        <pose>0.10000000000000001 0 0.059999999999999998 0 0 0</pose>
        <sensor name='front_camera' type='camera'>
          <pose>0 0 0 0 0 0</pose>
          <topic>image</topic>
          <update_rate>15</update_rate>
          <enable_metrics>false</enable_metrics>
          <camera name='__default__'>
            <pose>0 0 0 0 0 0</pose>
            <horizontal_fov>1.0469999999999999</horizontal_fov>
            <image>
              <width>320</width>
              <height>240</height>
              <format>RGB_INT8</format>
              <anti_aliasing>4</anti_aliasing>
            </image>
            <camera_info_topic>__default__</camera_info_topic>
            <trigger_topic></trigger_topic>
            <triggered>false</triggered>
            <clip>
              <near>0.02</near>
              <far>20</far>
            </clip>
            <save enabled='false'>
              <path>__default__</path>
            </save>
            <visibility_mask>4294967295</visibility_mask>
            <noise>
              <type>none</type>
              <mean>0</mean>
              <stddev>0</stddev>
            </noise>
            <distortion>
              <k1>0</k1>
              <k2>0</k2>
              <k3>0</k3>
              <p1>0</p1>
              <p2>0</p2>
              <center>0.5 0.5</center>
            </distortion>
            <lens>
              <type>stereographic</type>
              <scale_to_hfov>true</scale_to_hfov>
              <cutoff_angle>1.5707963267948966</cutoff_angle>
              <env_texture_size>256</env_texture_size>
            </lens>
            <optical_frame_id></optical_frame_id>
          </camera>
        </sensor>
        <inertial>
          <pose>0 0 0 0 0 0</pose>
          <mass>1</mass>
          <inertia>
            <ixx>1</ixx>
            <ixy>0</ixy>
            <ixz>0</ixz>
            <iyy>1</iyy>
            <iyz>0</iyz>
            <izz>1</izz>
          </inertia>
        </inertial>
        <enable_wind>false</enable_wind>
      </link>
      <plugin name='diff_drive' filename='gz-sim-diff-drive-system'>
        <left_joint>left_wheel_joint</left_joint>
        <right_joint>right_wheel_joint</right_joint>
        <wheel_separation>0.13</wheel_separation>
        <wheel_radius>0.03</wheel_radius>
        <odom_publish_frequency>20</odom_publish_frequency>
      </plugin>
      <self_collide>false</self_collide>
    </model>
    <light name='sun' type='directional'>
      <pose>0 0 0 0 0 0</pose>
      <cast_shadows>true</cast_shadows>
      <intensity>1</intensity>
      <direction>-0.5 0.5 -1</direction>
      <diffuse>1 1 1 1</diffuse>
      <specular>0.100000001 0.100000001 0.100000001 1</specular>
      <attenuation>
        <range>10</range>
        <linear>1</linear>
        <constant>1</constant>
        <quadratic>0</quadratic>
      </attenuation>
      <spot>
        <inner_angle>0</inner_angle>
        <outer_angle>0</outer_angle>
        <falloff>0</falloff>
      </spot>
    </light>
  </world>
</sdf>
